Workbook
Name dAge: Data!$K$2:$K$5001
Name dCamp: Data!$AA$2:$AA$5001
Name dCat: Data!$P$2:$P$5001
Name dChan: Data!$Z$2:$Z$5001
Name dCity: Data!$L$2:$L$5001
Name dCost: Data!$V$2:$V$5001
Name dCust: Data!$G$2:$G$5001
Name dDisc: Data!$T$2:$T$5001
Name dGen: Data!$I$2:$I$5001
Name dMkt: Data!$AD$2:$AD$5001
Name dMon: Data!$AF$2:$AF$5001
Name dNet: Data!$AE$2:$AE$5001
Name dPay: Data!$X$2:$X$5001
Name dProd: Data!$O$2:$O$5001
Name dProfit: Data!$W$2:$W$5001
Name dQty: Data!$R$2:$R$5001
Name dRate: Data!$AB$2:$AB$5001
Name dSales: Data!$U$2:$U$5001
Name dShip: Data!$AC$2:$AC$5001
Name dState: Data!$M$2:$M$5001
Name dStatus: Data!$Y$2:$Y$5001
Name dSub: Data!$Q$2:$Q$5001
Name dVis: Data!$AG$2:$AG$5001
Name dYear: Data!$C$2:$C$5001
Name selCat: Dashboard!$I$4
Name selState: Dashboard!$J$4
Name selYear: Dashboard!$H$4
Name Slicer_Category: #N/A
Name Slicer_State: #N/A
Name Slicer_Year: #N/A

Sheet Dashboard
A1: E-COMMERCE BUSINESS INTELLIGENCE SYSTEM
A2: Sales · Customer · Product · Marketing · Profitability | Jan 2025 – Sep 2026 | Choose filters below (yellow cells)
H3: criteria (do not edit)
A4: Year | B4: All | C4: Category | D4: All | E4: State | F4: All | H4: =IF(B4="All","<>",VALUE(B4)) -> <> | I4: =IF(D4="All","<>",D4) -> <> | J4: =IF(F4="All","<>",F4) -> <>
A6: Total Revenue | C6: Orders | E6: Avg Order Value | G6: Units Sold | I6: Return Rate | K6: Cancel Rate
A7: =SUMIFS(dSales,dYear,selYear,dCat,selCat,dState,selState,dVis,1) -> 30874665 | C7: =COUNTIFS(dYear,selYear,dCat,selCat,dState,selState,dVis,1) -> 5000 | E7: =IFERROR(A7/COUNTIFS(dYear,selYear,dCat,selCat,dState,selState,dVis,1,dStatus,"<>Cancelled"),0) -> 6535.7038 | G7: =SUMIFS(dQty,dYear,selYear,dCat,selCat,dState,selState,dVis,1) -> 11042 | I7: =IFERROR(COUNTIFS(dYear,selYear,dCat,selCat,dState,selState,dVis,1,dStatus,"Returned")/C7,0) -> 0.07 | K7: =IFERROR(COUNTIFS(dYear,selYear,dCat,selCat,dState,selState,dVis,1,dStatus,"Cancelled")/C7,0) -> 0.0552
A9: Gross Profit | C9: Gross Margin | E9: Net Profit | G9: Net Margin | I9: Marketing Spend | K9: ROAS (Revenue / Mkt Cost)
A10: =SUMIFS(dProfit,dYear,selYear,dCat,selCat,dState,selState,dVis,1) -> 9717464.7 | C10: =IFERROR(A10/A7,0) -> 0.31473912 | E10: =SUMIFS(dNet,dYear,selYear,dCat,selCat,dState,selState,dVis,1) -> 7080825.3 | G10: =IFERROR(E10/A7,0) -> 0.22934096 | I10: =SUMIFS(dMkt,dYear,selYear,dCat,selCat,dState,selState,dVis,1) -> 2306889.4 | K10: =IFERROR(A7/I10,0) -> 13.383678
A11: Slicers: click a button to filter every sheet (Ctrl+click = multi-select, funnel-X icon = clear). Works together with the Year / Category / State dropdowns above.

Sheet Sales
A1: Sales Analytics
A2: Filtered by Dashboard selections (Year / Category / State)
A4: Monthly Sales Trend
A5: Month | B5: Orders | C5: Revenue | D5: Units | E5: Avg Order Value
A6: 2025-01 | B6: =COUNTIFS(dYear,selYear,dCat,selCat,dState,selState,dVis,1,dMon,$A6) -> 237 | C6: =SUMIFS(dSales,dYear,selYear,dCat,selCat,dState,selState,dVis,1,dMon,$A6) -> 1470563.4 | D6: =SUMIFS(dQty,dYear,selYear,dCat,selCat,dState,selState,dVis,1,dMon,$A6) -> 492 | E6: =IFERROR(C6/COUNTIFS(dYear,selYear,dCat,selCat,dState,selState,dVis,1,dMon,$A6,dStatus,"<>Cancelled"),0) -> 6565.015
A7: 2025-02 | B7: =COUNTIFS(dYear,selYear,dCat,selCat,dState,selState,dVis,1,dMon,$A7) -> 203 | C7: =SUMIFS(dSales,dYear,selYear,dCat,selCat,dState,selState,dVis,1,dMon,$A7) -> 1212539.9 | D7: =SUMIFS(dQty,dYear,selYear,dCat,selCat,dState,selState,dVis,1,dMon,$A7) -> 460 | E7: =IFERROR(C7/COUNTIFS(dYear,selYear,dCat,selCat,dState,selState,dVis,1,dMon,$A7,dStatus,"<>Cancelled"),0) -> 6449.6801
A8: 2025-03 | B8: =COUNTIFS(dYear,selYear,dCat,selCat,dState,selState,dVis,1,dMon,$A8) -> 274 | C8: =SUMIFS(dSales,dYear,selYear,dCat,selCat,dState,selState,dVis,1,dMon,$A8) -> 1706082.2 | D8: =SUMIFS(dQty,dYear,selYear,dCat,selCat,dState,selState,dVis,1,dMon,$A8) -> 609 | E8: =IFERROR(C8/COUNTIFS(dYear,selYear,dCat,selCat,dState,selState,dVis,1,dMon,$A8,dStatus,"<>Cancelled"),0) -> 6612.7217
A9: 2025-04 | B9: =COUNTIFS(dYear,selYear,dCat,selCat,dState,selState,dVis,1,dMon,$A9) -> 236 | C9: =SUMIFS(dSales,dYear,selYear,dCat,selCat,dState,selState,dVis,1,dMon,$A9) -> 1389047 | D9: =SUMIFS(dQty,dYear,selYear,dCat,selCat,dState,selState,dVis,1,dMon,$A9) -> 519 | E9: =IFERROR(C9/COUNTIFS(dYear,selYear,dCat,selCat,dState,selState,dVis,1,dMon,$A9,dStatus,"<>Cancelled"),0) -> 6430.7731
A10: 2025-05 | B10: =COUNTIFS(dYear,selYear,dCat,selCat,dState,selState,dVis,1,dMon,$A10) -> 246 | C10: =SUMIFS(dSales,dYear,selYear,dCat,selCat,dState,selState,dVis,1,dMon,$A10) -> 1694242.9 | D10: =SUMIFS(dQty,dYear,selYear,dCat,selCat,dState,selState,dVis,1,dMon,$A10) -> 556 | E10: =IFERROR(C10/COUNTIFS(dYear,selYear,dCat,selCat,dState,selState,dVis,1,dMon,$A10,dStatus,"<>Cancelled"),0) -> 7240.3541
A11: 2025-06 | B11: =COUNTIFS(dYear,selYear,dCat,selCat,dState,selState,dVis,1,dMon,$A11) -> 232 | C11: =SUMIFS(dSales,dYear,selYear,dCat,selCat,dState,selState,dVis,1,dMon,$A11) -> 1448851 | D11: =SUMIFS(dQty,dYear,selYear,dCat,selCat,dState,selState,dVis,1,dMon,$A11) -> 519 | E11: =IFERROR(C11/COUNTIFS(dYear,selYear,dCat,selCat,dState,selState,dVis,1,dMon,$A11,dStatus,"<>Cancelled"),0) -> 6555.8869
A12: 2025-07 | B12: =COUNTIFS(dYear,selYear,dCat,selCat,dState,selState,dVis,1,dMon,$A12) -> 253 | C12: =SUMIFS(dSales,dYear,selYear,dCat,selCat,dState,selState,dVis,1,dMon,$A12) -> 1639832.2 | D12: =SUMIFS(dQty,dYear,selYear,dCat,selCat,dState,selState,dVis,1,dMon,$A12) -> 559 | E12: =IFERROR(C12/COUNTIFS(dYear,selYear,dCat,selCat,dState,selState,dVis,1,dMon,$A12,dStatus,"<>Cancelled"),0) -> 6948.4413
A13: 2025-08 | B13: =COUNTIFS(dYear,selYear,dCat,selCat,dState,selState,dVis,1,dMon,$A13) -> 250 | C13: =SUMIFS(dSales,dYear,selYear,dCat,selCat,dState,selState,dVis,1,dMon,$A13) -> 1440786.9 | D13: =SUMIFS(dQty,dYear,selYear,dCat,selCat,dState,selState,dVis,1,dMon,$A13) -> 542 | E13: =IFERROR(C13/COUNTIFS(dYear,selYear,dCat,selCat,dState,selState,dVis,1,dMon,$A13,dStatus,"<>Cancelled"),0) -> 6003.2788
A14: 2025-09 | B14: =COUNTIFS(dYear,selYear,dCat,selCat,dState,selState,dVis,1,dMon,$A14) -> 226 | C14: =SUMIFS(dSales,dYear,selYear,dCat,selCat,dState,selState,dVis,1,dMon,$A14) -> 1530080.5 | D14: =SUMIFS(dQty,dYear,selYear,dCat,selCat,dState,selState,dVis,1,dMon,$A14) -> 498 | E14: =IFERROR(C14/COUNTIFS(dYear,selYear,dCat,selCat,dState,selState,dVis,1,dMon,$A14,dStatus,"<>Cancelled"),0) -> 7051.0622
A15: 2025-10 | B15: =COUNTIFS(dYear,selYear,dCat,selCat,dState,selState,dVis,1,dMon,$A15) -> 226 | C15: =SUMIFS(dSales,dYear,selYear,dCat,selCat,dState,selState,dVis,1,dMon,$A15) -> 1550397.8 | D15: =SUMIFS(dQty,dYear,selYear,dCat,selCat,dState,selState,dVis,1,dMon,$A15) -> 503 | E15: =IFERROR(C15/COUNTIFS(dYear,selYear,dCat,selCat,dState,selState,dVis,1,dMon,$A15,dStatus,"<>Cancelled"),0) -> 7047.2627
A16: 2025-11 | B16: =COUNTIFS(dYear,selYear,dCat,selCat,dState,selState,dVis,1,dMon,$A16) -> 243 | C16: =SUMIFS(dSales,dYear,selYear,dCat,selCat,dState,selState,dVis,1,dMon,$A16) -> 1500454.8 | D16: =SUMIFS(dQty,dYear,selYear,dCat,selCat,dState,selState,dVis,1,dMon,$A16) -> 548 | E16: =IFERROR(C16/COUNTIFS(dYear,selYear,dCat,selCat,dState,selState,dVis,1,dMon,$A16,dStatus,"<>Cancelled"),0) -> 6609.9328
A17: 2025-12 | B17: =COUNTIFS(dYear,selYear,dCat,selCat,dState,selState,dVis,1,dMon,$A17) -> 217 | C17: =SUMIFS(dSales,dYear,selYear,dCat,selCat,dState,selState,dVis,1,dMon,$A17) -> 1350451.9 | D17: =SUMIFS(dQty,dYear,selYear,dCat,selCat,dState,selState,dVis,1,dMon,$A17) -> 493 | E17: =IFERROR(C17/COUNTIFS(dYear,selYear,dCat,selCat,dState,selState,dVis,1,dMon,$A17,dStatus,"<>Cancelled"),0) -> 6652.4727
... A26: 2026-09 | B26: =COUNTIFS(dYear,selYear,dCat,selCat,dState,selState,dVis,1,dMon,$A26) -> 233 | C26: =SUMIFS(dSales,dYear,selYear,dCat,selCat,dState,selState,dVis,1,dMon,$A26) -> 1371573 | D26: =SUMIFS(dQty,dYear,selYear,dCat,selCat,dState,selState,dVis,1,dMon,$A26) -> 506 | E26: =IFERROR(C26/COUNTIFS(dYear,selYear,dCat,selCat,dState,selState,dVis,1,dMon,$A26,dStatus,"<>Cancelled"),0) -> 6291.619
A29: Revenue by Category
A30: Category | B30: Orders | C30: Revenue | D30: Units | E30: Share
A31: Electronics | B31: =COUNTIFS(dYear,selYear,dCat,selCat,dState,selState,dVis,1,dCat,$A31) -> 1190 | C31: =SUMIFS(dSales,dYear,selYear,dCat,selCat,dState,selState,dVis,1,dCat,$A31) -> 15609511 | D31: =SUMIFS(dQty,dYear,selYear,dCat,selCat,dState,selState,dVis,1,dCat,$A31) -> 2588 | E31: =IFERROR(C31/SUM(C$31:C$36),0) -> 0.50557671
A32: Home & Kitchen | B32: =COUNTIFS(dYear,selYear,dCat,selCat,dState,selState,dVis,1,dCat,$A32) -> 1282 | C32: =SUMIFS(dSales,dYear,selYear,dCat,selCat,dState,selState,dVis,1,dCat,$A32) -> 7516883.5 | D32: =SUMIFS(dQty,dYear,selYear,dCat,selCat,dState,selState,dVis,1,dCat,$A32) -> 2882 | E32: =IFERROR(C32/SUM(C$31:C$36),0) -> 0.24346446
A33: Fashion | B33: =COUNTIFS(dYear,selYear,dCat,selCat,dState,selState,dVis,1,dCat,$A33) -> 995 | C33: =SUMIFS(dSales,dYear,selYear,dCat,selCat,dState,selState,dVis,1,dCat,$A33) -> 2995938.5 | D33: =SUMIFS(dQty,dYear,selYear,dCat,selCat,dState,selState,dVis,1,dCat,$A33) -> 2159 | E33: =IFERROR(C33/SUM(C$31:C$36),0) -> 0.097035499
A34: Beauty | B34: =COUNTIFS(dYear,selYear,dCat,selCat,dState,selState,dVis,1,dCat,$A34) -> 501 | C34: =SUMIFS(dSales,dYear,selYear,dCat,selCat,dState,selState,dVis,1,dCat,$A34) -> 1904279.3 | D34: =SUMIFS(dQty,dYear,selYear,dCat,selCat,dState,selState,dVis,1,dCat,$A34) -> 1132 | E34: =IFERROR(C34/SUM(C$31:C$36),0) -> 0.061677732
A35: Sports | B35: =COUNTIFS(dYear,selYear,dCat,selCat,dState,selState,dVis,1,dCat,$A35) -> 503 | C35: =SUMIFS(dSales,dYear,selYear,dCat,selCat,dState,selState,dVis,1,dCat,$A35) -> 1600075 | D35: =SUMIFS(dQty,dYear,selYear,dCat,selCat,dState,selState,dVis,1,dCat,$A35) -> 1131 | E35: =IFERROR(C35/SUM(C$31:C$36),0) -> 0.051824853
A36: Accessories | B36: =COUNTIFS(dYear,selYear,dCat,selCat,dState,selState,dVis,1,dCat,$A36) -> 529 | C36: =SUMIFS(dSales,dYear,selYear,dCat,selCat,dState,selState,dVis,1,dCat,$A36) -> 1247977.1 | D36: =SUMIFS(dQty,dYear,selYear,dCat,selCat,dState,selState,dVis,1,dCat,$A36) -> 1150 | E36: =IFERROR(C36/SUM(C$31:C$36),0) -> 0.040420748
A47: Revenue by State
A48: State | B48: Orders | C48: Revenue | D48: Units
A49: Uttar Pradesh | B49: =COUNTIFS(dYear,selYear,dCat,selCat,dState,selState,dVis,1,dState,$A49) -> 1122 | C49: =SUMIFS(dSales,dYear,selYear,dCat,selCat,dState,selState,dVis,1,dState,$A49) -> 7224772.3 | D49: =SUMIFS(dQty,dYear,selYear,dCat,selCat,dState,selState,dVis,1,dState,$A49) -> 2489
A50: Maharashtra | B50: =COUNTIFS(dYear,selYear,dCat,selCat,dState,selState,dVis,1,dState,$A50) -> 722 | C50: =SUMIFS(dSales,dYear,selYear,dCat,selCat,dState,selState,dVis,1,dState,$A50) -> 4399844.5 | D50: =SUMIFS(dQty,dYear,selYear,dCat,selCat,dState,selState,dVis,1,dState,$A50) -> 1609
A51: Karnataka | B51: =COUNTIFS(dYear,selYear,dCat,selCat,dState,selState,dVis,1,dState,$A51) -> 553 | C51: =SUMIFS(dSales,dYear,selYear,dCat,selCat,dState,selState,dVis,1,dState,$A51) -> 3585568 | D51: =SUMIFS(dQty,dYear,selYear,dCat,selCat,dState,selState,dVis,1,dState,$A51) -> 1245
A52: Tamil Nadu | B52: =COUNTIFS(dYear,selYear,dCat,selCat,dState,selState,dVis,1,dState,$A52) -> 545 | C52: =SUMIFS(dSales,dYear,selYear,dCat,selCat,dState,selState,dVis,1,dState,$A52) -> 3277211.2 | D52: =SUMIFS(dQty,dYear,selYear,dCat,selCat,dState,selState,dVis,1,dState,$A52) -> 1211
A53: Delhi | B53: =COUNTIFS(dYear,selYear,dCat,selCat,dState,selState,dVis,1,dState,$A53) -> 464 | C53: =SUMIFS(dSales,dYear,selYear,dCat,selCat,dState,selState,dVis,1,dState,$A53) -> 2986182.7 | D53: =SUMIFS(dQty,dYear,selYear,dCat,selCat,dState,selState,dVis,1,dState,$A53) -> 1003
A54: Rajasthan | B54: =COUNTIFS(dYear,selYear,dCat,selCat,dState,selState,dVis,1,dState,$A54) -> 370 | C54: =SUMIFS(dSales,dYear,selYear,dCat,selCat,dState,selState,dVis,1,dState,$A54) -> 2241649.6 | D54: =SUMIFS(dQty,dYear,selYear,dCat,selCat,dState,selState,dVis,1,dState,$A54) -> 836
A55: Telangana | B55: =COUNTIFS(dYear,selYear,dCat,selCat,dState,selState,dVis,1,dState,$A55) -> 367 | C55: =SUMIFS(dSales,dYear,selYear,dCat,selCat,dState,selState,dVis,1,dState,$A55) -> 2127694.3 | D55: =SUMIFS(dQty,dYear,selYear,dCat,selCat,dState,selState,dVis,1,dState,$A55) -> 825
A56: Gujarat | B56: =COUNTIFS(dYear,selYear,dCat,selCat,dState,selState,dVis,1,dState,$A56) -> 332 | C56: =SUMIFS(dSales,dYear,selYear,dCat,selCat,dState,selState,dVis,1,dState,$A56) -> 2047458 | D56: =SUMIFS(dQty,dYear,selYear,dCat,selCat,dState,selState,dVis,1,dState,$A56) -> 730
A57: West Bengal | B57: =COUNTIFS(dYear,selYear,dCat,selCat,dState,selState,dVis,1,dState,$A57) -> 289 | C57: =SUMIFS(dSales,dYear,selYear,dCat,selCat,dState,selState,dVis,1,dState,$A57) -> 1549076.4 | D57: =SUMIFS(dQty,dYear,selYear,dCat,selCat,dState,selState,dVis,1,dState,$A57) -> 588
A58: Bihar | B58: =COUNTIFS(dYear,selYear,dCat,selCat,dState,selState,dVis,1,dState,$A58) -> 236 | C58: =SUMIFS(dSales,dYear,selYear,dCat,selCat,dState,selState,dVis,1,dState,$A58) -> 1435207.8 | D58: =SUMIFS(dQty,dYear,selYear,dCat,selCat,dState,selState,dVis,1,dState,$A58) -> 506
A65: Order Status
A66: Status | B66: Orders | C66: Revenue | D66: % of Orders
A67: Delivered | B67: =COUNTIFS(dYear,selYear,dCat,selCat,dState,selState,dVis,1,dStatus,$A67) -> 4219 | C67: =SUMIFS(dSales,dYear,selYear,dCat,selCat,dState,selState,dVis,1,dStatus,$A67) -> 27593494 | D67: =IFERROR(B67/SUM(B$67:B$70),0) -> 0.8438
...

Sheet Customers
A1: Customer Analytics
A2: Filtered by Dashboard selections (Year / Category / State)
A4: Age Group
A5: Age Group | B5: Orders | C5: Revenue | D5: Avg Order Value
A6: 18-25 | B6: =COUNTIFS(dYear,selYear,dCat,selCat,dState,selState,dVis,1,dAge,$A6) -> 872 | C6: =SUMIFS(dSales,dYear,selYear,dCat,selCat,dState,selState,dVis,1,dAge,$A6) -> 5057996.1 | D6: =IFERROR(C6/COUNTIFS(dYear,selYear,dCat,selCat,dState,selState,dVis,1,dAge,$A6,dStatus,"<>Cancelled"),0) -> 6175.8195
A7: 26-35 | B7: =COUNTIFS(dYear,selYear,dCat,selCat,dState,selState,dVis,1,dAge,$A7) -> 1259 | C7: =SUMIFS(dSales,dYear,selYear,dCat,selCat,dState,selState,dVis,1,dAge,$A7) -> 8149708.1 | D7: =IFERROR(C7/COUNTIFS(dYear,selYear,dCat,selCat,dState,selState,dVis,1,dAge,$A7,dStatus,"<>Cancelled"),0) -> 6831.2725
A8: 36-45 | B8: =COUNTIFS(dYear,selYear,dCat,selCat,dState,selState,dVis,1,dAge,$A8) -> 1200 | C8: =SUMIFS(dSales,dYear,selYear,dCat,selCat,dState,selState,dVis,1,dAge,$A8) -> 7469763.2 | D8: =IFERROR(C8/COUNTIFS(dYear,selYear,dCat,selCat,dState,selState,dVis,1,dAge,$A8,dStatus,"<>Cancelled"),0) -> 6663.4819
A9: 46-60 | B9: =COUNTIFS(dYear,selYear,dCat,selCat,dState,selState,dVis,1,dAge,$A9) -> 1669 | C9: =SUMIFS(dSales,dYear,selYear,dCat,selCat,dState,selState,dVis,1,dAge,$A9) -> 10197197 | D9: =IFERROR(C9/COUNTIFS(dYear,selYear,dCat,selCat,dState,selState,dVis,1,dAge,$A9,dStatus,"<>Cancelled"),0) -> 6409.3005
A22: Gender
A23: Gender | B23: Orders | C23: Revenue
A24: Male | B24: =COUNTIFS(dYear,selYear,dCat,selCat,dState,selState,dVis,1,dGen,$A24) -> 2544 | C24: =SUMIFS(dSales,dYear,selYear,dCat,selCat,dState,selState,dVis,1,dGen,$A24) -> 15638453
A25: Female | B25: =COUNTIFS(dYear,selYear,dCat,selCat,dState,selState,dVis,1,dGen,$A25) -> 2328 | C25: =SUMIFS(dSales,dYear,selYear,dCat,selCat,dState,selState,dVis,1,dGen,$A25) -> 14486127
A26: Other | B26: =COUNTIFS(dYear,selYear,dCat,selCat,dState,selState,dVis,1,dGen,$A26) -> 128 | C26: =SUMIFS(dSales,dYear,selYear,dCat,selCat,dState,selState,dVis,1,dGen,$A26) -> 750084.9
A40: Top Cities
A41: City | B41: Orders | C41: Revenue
A42: Kanpur | B42: =COUNTIFS(dYear,selYear,dCat,selCat,dState,selState,dVis,1,dCity,$A42) -> 291 | C42: =SUMIFS(dSales,dYear,selYear,dCat,selCat,dState,selState,dVis,1,dCity,$A42) -> 1676910.4
A43: Varanasi | B43: =COUNTIFS(dYear,selYear,dCat,selCat,dState,selState,dVis,1,dCity,$A43) -> 214 | C43: =SUMIFS(dSales,dYear,selYear,dCat,selCat,dState,selState,dVis,1,dCity,$A43) -> 1586589.3
A44: Delhi | B44: =COUNTIFS(dYear,selYear,dCat,selCat,dState,selState,dVis,1,dCity,$A44) -> 221 | C44: =SUMIFS(dSales,dYear,selYear,dCat,selCat,dState,selState,dVis,1,dCity,$A44) -> 1525740.5
A45: New Delhi | B45: =COUNTIFS(dYear,selYear,dCat,selCat,dState,selState,dVis,1,dCity,$A45) -> 243 | C45: =SUMIFS(dSales,dYear,selYear,dCat,selCat,dState,selState,dVis,1,dCity,$A45) -> 1460442.1
A46: Lucknow | B46: =COUNTIFS(dYear,selYear,dCat,selCat,dState,selState,dVis,1,dCity,$A46) -> 249 | C46: =SUMIFS(dSales,dYear,selYear,dCat,selCat,dState,selState,dVis,1,dCity,$A46) -> 1435830.6
A47: Mysuru | B47: =COUNTIFS(dYear,selYear,dCat,selCat,dState,selState,dVis,1,dCity,$A47) -> 229 | C47: =SUMIFS(dSales,dYear,selYear,dCat,selCat,dState,selState,dVis,1,dCity,$A47) -> 1396018.6
A48: Pune | B48: =COUNTIFS(dYear,selYear,dCat,selCat,dState,selState,dVis,1,dCity,$A48) -> 205 | C48: =SUMIFS(dSales,dYear,selYear,dCat,selCat,dState,selState,dVis,1,dCity,$A48) -> 1350362
A49: Noida | B49: =COUNTIFS(dYear,selYear,dCat,selCat,dState,selState,dVis,1,dCity,$A49) -> 187 | C49: =SUMIFS(dSales,dYear,selYear,dCat,selCat,dState,selState,dVis,1,dCity,$A49) -> 1279791.8
A50: Bengaluru | B50: =COUNTIFS(dYear,selYear,dCat,selCat,dState,selState,dVis,1,dCity,$A50) -> 189 | C50: =SUMIFS(dSales,dYear,selYear,dCat,selCat,dState,selState,dVis,1,dCity,$A50) -> 1270074.8
A51: Gorakhpur | B51: =COUNTIFS(dYear,selYear,dCat,selCat,dState,selState,dVis,1,dCity,$A51) -> 181 | C51: =SUMIFS(dSales,dYear,selYear,dCat,selCat,dState,selState,dVis,1,dCity,$A51) -> 1245650.3
A52: Chennai | B52: =COUNTIFS(dYear,selYear,dCat,selCat,dState,selState,dVis,1,dCity,$A52) -> 209 | C52: =SUMIFS(dSales,dYear,selYear,dCat,selCat,dState,selState,dVis,1,dCity,$A52) -> 1197165.4
A53: Nagpur | B53: =COUNTIFS(dYear,selYear,dCat,selCat,dState,selState,dVis,1,dCity,$A53) -> 200 | C53: =SUMIFS(dSales,dYear,selYear,dCat,selCat,dState,selState,dVis,1,dCity,$A53) -> 1179946.8
A58: Customer KPIs (all-time)
A59: Unique Customers | B59: =COUNTA(Customer_List!A2:A1183) -> 1182
A60: Repeat Customers % | B60: =COUNTIF(Customer_List!C2:C1183,">1")/COUNTA(Customer_List!A2:A1183) -> 0.92724196
A61: Revenue / Customer | B61: =SUM(Customer_List!D2:D1183)/COUNTA(Customer_List!A2:A1183) -> 26120.698
A62: Orders / Customer | B62: =SUM(Customer_List!C2:C1183)/COUNTA(Customer_List!A2:A1183) -> 4.2301184
A66: Top 10 Customers by Revenue (all-time)
A67: Rank | B67: Customer | C67: Orders | D67: Revenue
A68: 1 | B68: =INDEX(Customer_List!$B$2:$B$1183,MATCH(LARGE(Customer_List!$E$2:$E$1183,$A68),Customer_List!$E$2:$E$1183,0)) -> Customer 149 | C68: =INDEX(Customer_List!$C$2:$C$1183,MATCH(LARGE(Customer_List!$E$2:$E$1183,$A68),Customer_List!$E$2:$E$1183,0)) -> 10 | D68: =INDEX(Customer_List!$D$2:$D$1183,MATCH(LARGE(Customer_List!$E$2:$E$1183,$A68),Customer_List!$E$2:$E$1183,0)) -> 151311.2
A69: 2 | B69: =INDEX(Customer_List!$B$2:$B$1183,MATCH(LARGE(Customer_List!$E$2:$E$1183,$A69),Customer_List!$E$2:$E$1183,0)) -> Customer 161 | C69: =INDEX(Customer_List!$C$2:$C$1183,MATCH(LARGE(Customer_List!$E$2:$E$1183,$A69),Customer_List!$E$2:$E$1183,0)) -> 7 | D69: =INDEX(Customer_List!$D$2:$D$1183,MATCH(LARGE(Customer_List!$E$2:$E$1183,$A69),Customer_List!$E$2:$E$1183,0)) -> 149180.35
A70: 3 | B70: =INDEX(Customer_List!$B$2:$B$1183,MATCH(LARGE(Customer_List!$E$2:$E$1183,$A70),Customer_List!$E$2:$E$1183,0)) -> Customer 960 | C70: =INDEX(Customer_List!$C$2:$C$1183,MATCH(LARGE(Customer_List!$E$2:$E$1183,$A70),Customer_List!$E$2:$E$1183,0)) -> 7 | D70: =INDEX(Customer_List!$D$2:$D$1183,MATCH(LARGE(Customer_List!$E$2:$E$1183,$A70),Customer_List!$E$2:$E$1183,0)) -> 118298.4
A71: 4 | B71: =INDEX(Customer_List!$B$2:$B$1183,MATCH(LARGE(Customer_List!$E$2:$E$1183,$A71),Customer_List!$E$2:$E$1183,0)) -> Customer 986 | C71: =INDEX(Customer_List!$C$2:$C$1183,MATCH(LARGE(Customer_List!$E$2:$E$1183,$A71),Customer_List!$E$2:$E$1183,0)) -> 5 | D71: =INDEX(Customer_List!$D$2:$D$1183,MATCH(LARGE(Customer_List!$E$2:$E$1183,$A71),Customer_List!$E$2:$E$1183,0)) -> 116497.4
A72: 5 | B72: =INDEX(Customer_List!$B$2:$B$1183,MATCH(LARGE(Customer_List!$E$2:$E$1183,$A72),Customer_List!$E$2:$E$1183,0)) -> Customer 97 | C72: =INDEX(Customer_List!$C$2:$C$1183,MATCH(LARGE(Customer_List!$E$2:$E$1183,$A72),Customer_List!$E$2:$E$1183,0)) -> 6 | D72: =INDEX(Customer_List!$D$2:$D$1183,MATCH(LARGE(Customer_List!$E$2:$E$1183,$A72),Customer_List!$E$2:$E$1183,0)) -> 112896.7
A73: 6 | B73: =INDEX(Customer_List!$B$2:$B$1183,MATCH(LARGE(Customer_List!$E$2:$E$1183,$A73),Customer_List!$E$2:$E$1183,0)) -> Customer 484 | C73: =INDEX(Customer_List!$C$2:$C$1183,MATCH(LARGE(Customer_List!$E$2:$E$1183,$A73),Customer_List!$E$2:$E$1183,0)) -> 10 | D73: =INDEX(Customer_List!$D$2:$D$1183,MATCH(LARGE(Customer_List!$E$2:$E$1183,$A73),Customer_List!$E$2:$E$1183,0)) -> 110155.25
...

Sheet Products
A1: Product Analytics
A2: Filtered by Dashboard selections (Year / Category / State)
A4: Product Performance
A5: Product | B5: Category | C5: Units | D5: Revenue | E5: Gross Profit | F5: Margin | G5: Return % | H5: Avg Rating
A6: Tablet | B6: =INDEX(Data!$P$2:$P$5001,MATCH($A6,dProd,0)) -> Electronics | C6: =SUMIFS(dQty,dYear,selYear,dCat,selCat,dState,selState,dVis,1,dProd,$A6) -> 511 | D6: =SUMIFS(dSales,dYear,selYear,dCat,selCat,dState,selState,dVis,1,dProd,$A6) -> 5787804.7 | E6: =SUMIFS(dProfit,dYear,selYear,dCat,selCat,dState,selState,dVis,1,dProd,$A6) -> 1377804.8 | F6: =IFERROR(E6/D6,0) -> 0.23805308 | G6: =IFERROR(COUNTIFS(dYear,selYear,dCat,selCat,dState,selState,dVis,1,dProd,$A6,dStatus,"Returned")/COUNTIFS(dYear,selYear,dCat,selCat,dState,selState,dVis,1,dProd,$A6),0) -> 0.052631579 | H6: =IFERROR(AVERAGEIFS(dRate,dYear,selYear,dCat,selCat,dState,selState,dVis,1,dProd,$A6),0) -> 4.0789474
A7: Mobile Phone | B7: =INDEX(Data!$P$2:$P$5001,MATCH($A7,dProd,0)) -> Electronics | C7: =SUMIFS(dQty,dYear,selYear,dCat,selCat,dState,selState,dVis,1,dProd,$A7) -> 443 | D7: =SUMIFS(dSales,dYear,selYear,dCat,selCat,dState,selState,dVis,1,dProd,$A7) -> 5785114.3 | E7: =SUMIFS(dProfit,dYear,selYear,dCat,selCat,dState,selState,dVis,1,dProd,$A7) -> 1013914.3 | F7: =IFERROR(E7/D7,0) -> 0.17526262 | G7: =IFERROR(COUNTIFS(dYear,selYear,dCat,selCat,dState,selState,dVis,1,dProd,$A7,dStatus,"Returned")/COUNTIFS(dYear,selYear,dCat,selCat,dState,selState,dVis,1,dProd,$A7),0) -> 0.059360731 | H7: =IFERROR(AVERAGEIFS(dRate,dYear,selYear,dCat,selCat,dState,selState,dVis,1,dProd,$A7),0) -> 4.1077626
A8: Office Chair | B8: =INDEX(Data!$P$2:$P$5001,MATCH($A8,dProd,0)) -> Home & Kitchen | C8: =SUMIFS(dQty,dYear,selYear,dCat,selCat,dState,selState,dVis,1,dProd,$A8) -> 602 | D8: =SUMIFS(dSales,dYear,selYear,dCat,selCat,dState,selState,dVis,1,dProd,$A8) -> 3592936.6 | E8: =SUMIFS(dProfit,dYear,selYear,dCat,selCat,dState,selState,dVis,1,dProd,$A8) -> 1163436.7 | F8: =IFERROR(E8/D8,0) -> 0.32381218 | G8: =IFERROR(COUNTIFS(dYear,selYear,dCat,selCat,dState,selState,dVis,1,dProd,$A8,dStatus,"Returned")/COUNTIFS(dYear,selYear,dCat,selCat,dState,selState,dVis,1,dProd,$A8),0) -> 0.093023256 | H8: =IFERROR(AVERAGEIFS(dRate,dYear,selYear,dCat,selCat,dState,selState,dVis,1,dProd,$A8),0) -> 4.0565891
A9: Smart Watch | B9: =INDEX(Data!$P$2:$P$5001,MATCH($A9,dProd,0)) -> Electronics | C9: =SUMIFS(dQty,dYear,selYear,dCat,selCat,dState,selState,dVis,1,dProd,$A9) -> 583 | D9: =SUMIFS(dSales,dYear,selYear,dCat,selCat,dState,selState,dVis,1,dProd,$A9) -> 1964508.8 | E9: =SUMIFS(dProfit,dYear,selYear,dCat,selCat,dState,selState,dVis,1,dProd,$A9) -> 661308.75 | F9: =IFERROR(E9/D9,0) -> 0.33662805 | G9: =IFERROR(COUNTIFS(dYear,selYear,dCat,selCat,dState,selState,dVis,1,dProd,$A9,dStatus,"Returned")/COUNTIFS(dYear,selYear,dCat,selCat,dState,selState,dVis,1,dProd,$A9),0) -> 0.057251908 | H9: =IFERROR(AVERAGEIFS(dRate,dYear,selYear,dCat,selCat,dState,selState,dVis,1,dProd,$A9),0) -> 4.0625954
A10: Coffee Maker | B10: =INDEX(Data!$P$2:$P$5001,MATCH($A10,dProd,0)) -> Home & Kitchen | C10: =SUMIFS(dQty,dYear,selYear,dCat,selCat,dState,selState,dVis,1,dProd,$A10) -> 557 | D10: =SUMIFS(dSales,dYear,selYear,dCat,selCat,dState,selState,dVis,1,dProd,$A10) -> 1659400.7 | E10: =SUMIFS(dProfit,dYear,selYear,dCat,selCat,dState,selState,dVis,1,dProd,$A10) -> 554800.75 | F10: =IFERROR(E10/D10,0) -> 0.33433801 | G10: =IFERROR(COUNTIFS(dYear,selYear,dCat,selCat,dState,selState,dVis,1,dProd,$A10,dStatus,"Returned")/COUNTIFS(dYear,selYear,dCat,selCat,dState,selState,dVis,1,dProd,$A10),0) -> 0.075396825 | H10: =IFERROR(AVERAGEIFS(dRate,dYear,selYear,dCat,selCat,dState,selState,dVis,1,dProd,$A10),0) -> 4.0972222
A11: Mixer Grinder | B11: =INDEX(Data!$P$2:$P$5001,MATCH($A11,dProd,0)) -> Home & Kitchen | C11: =SUMIFS(dQty,dYear,selYear,dCat,selCat,dState,selState,dVis,1,dProd,$A11) -> 550 | D11: =SUMIFS(dSales,dYear,selYear,dCat,selCat,dState,selState,dVis,1,dProd,$A11) -> 1312031.3 | E11: =SUMIFS(dProfit,dYear,selYear,dCat,selCat,dState,selState,dVis,1,dProd,$A11) -> 457331.25 | F11: =IFERROR(E11/D11,0) -> 0.34856735 | G11: =IFERROR(COUNTIFS(dYear,selYear,dCat,selCat,dState,selState,dVis,1,dProd,$A11,dStatus,"Returned")/COUNTIFS(dYear,selYear,dCat,selCat,dState,selState,dVis,1,dProd,$A11),0) -> 0.06614786 | H11: =IFERROR(AVERAGEIFS(dRate,dYear,selYear,dCat,selCat,dState,selState,dVis,1,dProd,$A11),0) -> 4.1163424
A12: Running Shoes | B12: =INDEX(Data!$P$2:$P$5001,MATCH($A12,dProd,0)) -> Fashion | C12: =SUMIFS(dQty,dYear,selYear,dCat,selCat,dState,selState,dVis,1,dProd,$A12) -> 495 | D12: =SUMIFS(dSales,dYear,selYear,dCat,selCat,dState,selState,dVis,1,dProd,$A12) -> 1236637.7 | E12: =SUMIFS(dProfit,dYear,selYear,dCat,selCat,dState,selState,dVis,1,dProd,$A12) -> 463137.65 | F12: =IFERROR(E12/D12,0) -> 0.37451363 | G12: =IFERROR(COUNTIFS(dYear,selYear,dCat,selCat,dState,selState,dVis,1,dProd,$A12,dStatus,"Returned")/COUNTIFS(dYear,selYear,dCat,selCat,dState,selState,dVis,1,dProd,$A12),0) -> 0.080508475 | H12: =IFERROR(AVERAGEIFS(dRate,dYear,selYear,dCat,selCat,dState,selState,dVis,1,dProd,$A12),0) -> 4.0690678
A13: Wireless Headphones | B13: =INDEX(Data!$P$2:$P$5001,MATCH($A13,dProd,0)) -> Electronics | C13: =SUMIFS(dQty,dYear,selYear,dCat,selCat,dState,selState,dVis,1,dProd,$A13) -> 547 | D13: =SUMIFS(dSales,dYear,selYear,dCat,selCat,dState,selState,dVis,1,dProd,$A13) -> 1200019.8 | E13: =SUMIFS(dProfit,dYear,selYear,dCat,selCat,dState,selState,dVis,1,dProd,$A13) -> 434419.8 | F13: =IFERROR(E13/D13,0) -> 0.36201053 | G13: =IFERROR(COUNTIFS(dYear,selYear,dCat,selCat,dState,selState,dVis,1,dProd,$A13,dStatus,"Returned")/COUNTIFS(dYear,selYear,dCat,selCat,dState,selState,dVis,1,dProd,$A13),0) -> 0.076612903 | H13: =IFERROR(AVERAGEIFS(dRate,dYear,selYear,dCat,selCat,dState,selState,dVis,1,dProd,$A13),0) -> 4.0294355
A14: Cricket Bat | B14: =INDEX(Data!$P$2:$P$5001,MATCH($A14,dProd,0)) -> Sports | C14: =SUMIFS(dQty,dYear,selYear,dCat,selCat,dState,selState,dVis,1,dProd,$A14) -> 536 | D14: =SUMIFS(dSales,dYear,selYear,dCat,selCat,dState,selState,dVis,1,dProd,$A14) -> 1137045 | E14: =SUMIFS(dProfit,dYear,selYear,dCat,selCat,dState,selState,dVis,1,dProd,$A14) -> 435645 | F14: =IFERROR(E14/D14,0) -> 0.38313787 | G14: =IFERROR(COUNTIFS(dYear,selYear,dCat,selCat,dState,selState,dVis,1,dProd,$A14,dStatus,"Returned")/COUNTIFS(dYear,selYear,dCat,selCat,dState,selState,dVis,1,dProd,$A14),0) -> 0.077253219 | H14: =IFERROR(AVERAGEIFS(dRate,dYear,selYear,dCat,selCat,dState,selState,dVis,1,dProd,$A14),0) -> 3.9776824
A15: Perfume | B15: =INDEX(Data!$P$2:$P$5001,MATCH($A15,dProd,0)) -> Beauty | C15: =SUMIFS(dQty,dYear,selYear,dCat,selCat,dState,selState,dVis,1,dProd,$A15) -> 551 | D15: =SUMIFS(dSales,dYear,selYear,dCat,selCat,dState,selState,dVis,1,dProd,$A15) -> 1103979.8 | E15: =SUMIFS(dProfit,dYear,selYear,dCat,selCat,dState,selState,dVis,1,dProd,$A15) -> 470379.8 | F15: =IFERROR(E15/D15,0) -> 0.42607646 | G15: =IFERROR(COUNTIFS(dYear,selYear,dCat,selCat,dState,selState,dVis,1,dProd,$A15,dStatus,"Returned")/COUNTIFS(dYear,selYear,dCat,selCat,dState,selState,dVis,1,dProd,$A15),0) -> 0.088353414 | H15: =IFERROR(AVERAGEIFS(dRate,dYear,selYear,dCat,selCat,dState,selState,dVis,1,dProd,$A15),0) -> 4.1068273
A16: Bluetooth Speaker | B16: =INDEX(Data!$P$2:$P$5001,MATCH($A16,dProd,0)) -> Electronics | C16: =SUMIFS(dQty,dYear,selYear,dCat,selCat,dState,selState,dVis,1,dProd,$A16) -> 504 | D16: =SUMIFS(dSales,dYear,selYear,dCat,selCat,dState,selState,dVis,1,dProd,$A16) -> 872063.75 | E16: =SUMIFS(dProfit,dYear,selYear,dCat,selCat,dState,selState,dVis,1,dProd,$A16) -> 321213.75 | F16: =IFERROR(E16/D16,0) -> 0.36833746 | G16: =IFERROR(COUNTIFS(dYear,selYear,dCat,selCat,dState,selState,dVis,1,dProd,$A16,dStatus,"Returned")/COUNTIFS(dYear,selYear,dCat,selCat,dState,selState,dVis,1,dProd,$A16),0) -> 0.068669528 | H16: =IFERROR(AVERAGEIFS(dRate,dYear,selYear,dCat,selCat,dState,selState,dVis,1,dProd,$A16),0) -> 4.1120172
A17: Jeans | B17: =INDEX(Data!$P$2:$P$5001,MATCH($A17,dProd,0)) -> Fashion | C17: =SUMIFS(dQty,dYear,selYear,dCat,selCat,dState,selState,dVis,1,dProd,$A17) -> 534 | D17: =SUMIFS(dSales,dYear,selYear,dCat,selCat,dState,selState,dVis,1,dProd,$A17) -> 805322.35 | E17: =SUMIFS(dProfit,dYear,selYear,dCat,selCat,dState,selState,dVis,1,dProd,$A17) -> 334122.35 | F17: =IFERROR(E17/D17,0) -> 0.41489268 | G17: =IFERROR(COUNTIFS(dYear,selYear,dCat,selCat,dState,selState,dVis,1,dProd,$A17,dStatus,"Returned")/COUNTIFS(dYear,selYear,dCat,selCat,dState,selState,dVis,1,dProd,$A17),0) -> 0.065502183 | H17: =IFERROR(AVERAGEIFS(dRate,dYear,selYear,dCat,selCat,dState,selState,dVis,1,dProd,$A17),0) -> 4.0462882
... A25: Water Bottle | B25: =INDEX(Data!$P$2:$P$5001,MATCH($A25,dProd,0)) -> Home & Kitchen | C25: =SUMIFS(dQty,dYear,selYear,dCat,selCat,dState,selState,dVis,1,dProd,$A25) -> 603 | D25: =SUMIFS(dSales,dYear,selYear,dCat,selCat,dState,selState,dVis,1,dProd,$A25) -> 313277 | E25: =SUMIFS(dProfit,dYear,selYear,dCat,selCat,dState,selState,dVis,1,dProd,$A25) -> 168777 | F25: =IFERROR(E25/D25,0) -> 0.53874686 | G25: =IFERROR(COUNTIFS(dYear,selYear,dCat,selCat,dState,selState,dVis,1,dProd,$A25,dStatus,"Returned")/COUNTIFS(dYear,selYear,dCat,selCat,dState,selState,dVis,1,dProd,$A25),0) -> 0.056603774 | H25: =IFERROR(AVERAGEIFS(dRate,dYear,selYear,dCat,selCat,dState,selState,dVis,1,dProd,$A25),0) -> 4.1022642
A32: Sub-Category Performance
A33: Sub-Category | B33: Units | C33: Revenue | D33: Gross Profit | E33: Margin
A34: Tablets | B34: =SUMIFS(dQty,dYear,selYear,dCat,selCat,dState,selState,dVis,1,dSub,$A34) -> 511 | C34: =SUMIFS(dSales,dYear,selYear,dCat,selCat,dState,selState,dVis,1,dSub,$A34) -> 5787804.7 | D34: =SUMIFS(dProfit,dYear,selYear,dCat,selCat,dState,selState,dVis,1,dSub,$A34) -> 1377804.8 | E34: =IFERROR(D34/C34,0) -> 0.23805308
A35: Mobiles | B35: =SUMIFS(dQty,dYear,selYear,dCat,selCat,dState,selState,dVis,1,dSub,$A35) -> 443 | C35: =SUMIFS(dSales,dYear,selYear,dCat,selCat,dState,selState,dVis,1,dSub,$A35) -> 5785114.3 | D35: =SUMIFS(dProfit,dYear,selYear,dCat,selCat,dState,selState,dVis,1,dSub,$A35) -> 1013914.3 | E35: =IFERROR(D35/C35,0) -> 0.17526262
A36: Furniture | B36: =SUMIFS(dQty,dYear,selYear,dCat,selCat,dState,selState,dVis,1,dSub,$A36) -> 602 | C36: =SUMIFS(dSales,dYear,selYear,dCat,selCat,dState,selState,dVis,1,dSub,$A36) -> 3592936.6 | D36: =SUMIFS(dProfit,dYear,selYear,dCat,selCat,dState,selState,dVis,1,dSub,$A36) -> 1163436.7 | E36: =IFERROR(D36/C36,0) -> 0.32381218
A37: Kitchen | B37: =SUMIFS(dQty,dYear,selYear,dCat,selCat,dState,selState,dVis,1,dSub,$A37) -> 1710 | C37: =SUMIFS(dSales,dYear,selYear,dCat,selCat,dState,selState,dVis,1,dSub,$A37) -> 3284709 | D37: =SUMIFS(dProfit,dYear,selYear,dCat,selCat,dState,selState,dVis,1,dSub,$A37) -> 1180909 | E37: =IFERROR(D37/C37,0) -> 0.35951708
A38: Audio | B38: =SUMIFS(dQty,dYear,selYear,dCat,selCat,dState,selState,dVis,1,dSub,$A38) -> 1051 | C38: =SUMIFS(dSales,dYear,selYear,dCat,selCat,dState,selState,dVis,1,dSub,$A38) -> 2072083.6 | D38: =SUMIFS(dProfit,dYear,selYear,dCat,selCat,dState,selState,dVis,1,dSub,$A38) -> 755633.55 | E38: =IFERROR(D38/C38,0) -> 0.3646733
A39: Wearables | B39: =SUMIFS(dQty,dYear,selYear,dCat,selCat,dState,selState,dVis,1,dSub,$A39) -> 583 | C39: =SUMIFS(dSales,dYear,selYear,dCat,selCat,dState,selState,dVis,1,dSub,$A39) -> 1964508.8 | D39: =SUMIFS(dProfit,dYear,selYear,dCat,selCat,dState,selState,dVis,1,dSub,$A39) -> 661308.75 | E39: =IFERROR(D39/C39,0) -> 0.33662805
A40: Bags | B40: =SUMIFS(dQty,dYear,selYear,dCat,selCat,dState,selState,dVis,1,dSub,$A40) -> 1150 | C40: =SUMIFS(dSales,dYear,selYear,dCat,selCat,dState,selState,dVis,1,dSub,$A40) -> 1247977.1 | D40: =SUMIFS(dProfit,dYear,selYear,dCat,selCat,dState,selState,dVis,1,dSub,$A40) -> 525377.05 | E40: =IFERROR(D40/C40,0) -> 0.42098294
A41: Footwear | B41: =SUMIFS(dQty,dYear,selYear,dCat,selCat,dState,selState,dVis,1,dSub,$A41) -> 495 | C41: =SUMIFS(dSales,dYear,selYear,dCat,selCat,dState,selState,dVis,1,dSub,$A41) -> 1236637.7 | D41: =SUMIFS(dProfit,dYear,selYear,dCat,selCat,dState,selState,dVis,1,dSub,$A41) -> 463137.65 | E41: =IFERROR(D41/C41,0) -> 0.37451363
A42: Clothing | B42: =SUMIFS(dQty,dYear,selYear,dCat,selCat,dState,selState,dVis,1,dSub,$A42) -> 1105 | C42: =SUMIFS(dSales,dYear,selYear,dCat,selCat,dState,selState,dVis,1,dSub,$A42) -> 1202545.2 | D42: =SUMIFS(dProfit,dYear,selYear,dCat,selCat,dState,selState,dVis,1,dSub,$A42) -> 518015.2 | E42: =IFERROR(D42/C42,0) -> 0.43076568
A43: Cricket | B43: =SUMIFS(dQty,dYear,selYear,dCat,selCat,dState,selState,dVis,1,dSub,$A43) -> 536 | C43: =SUMIFS(dSales,dYear,selYear,dCat,selCat,dState,selState,dVis,1,dSub,$A43) -> 1137045 | D43: =SUMIFS(dProfit,dYear,selYear,dCat,selCat,dState,selState,dVis,1,dSub,$A43) -> 435645 | E43: =IFERROR(D43/C43,0) -> 0.38313787
A44: Fragrance | B44: =SUMIFS(dQty,dYear,selYear,dCat,selCat,dState,selState,dVis,1,dSub,$A44) -> 551 | C44: =SUMIFS(dSales,dYear,selYear,dCat,selCat,dState,selState,dVis,1,dSub,$A44) -> 1103979.8 | D44: =SUMIFS(dProfit,dYear,selYear,dCat,selCat,dState,selState,dVis,1,dSub,$A44) -> 470379.8 | E44: =IFERROR(D44/C44,0) -> 0.42607646
A45: Skincare | B45: =SUMIFS(dQty,dYear,selYear,dCat,selCat,dState,selState,dVis,1,dSub,$A45) -> 581 | C45: =SUMIFS(dSales,dYear,selYear,dCat,selCat,dState,selState,dVis,1,dSub,$A45) -> 800299.5 | D45: =SUMIFS(dProfit,dYear,selYear,dCat,selCat,dState,selState,dVis,1,dSub,$A45) -> 365899.5 | E45: =IFERROR(D45/C45,0) -> 0.45720321
... A48: Fitness | B48: =SUMIFS(dQty,dYear,selYear,dCat,selCat,dState,selState,dVis,1,dSub,$A48) -> 595 | C48: =SUMIFS(dSales,dYear,selYear,dCat,selCat,dState,selState,dVis,1,dSub,$A48) -> 463029.95 | D48: =SUMIFS(dProfit,dYear,selYear,dCat,selCat,dState,selState,dVis,1,dSub,$A48) -> 225309.95 | E48: =IFERROR(D48/C48,0) -> 0.48659909

Sheet Marketing
A1: Marketing Analytics
A2: Filtered by Dashboard selections (Year / Category / State)
A4: Channel Performance
A5: Channel | B5: Orders | C5: Revenue | D5: Marketing Cost | E5: ROAS | F5: Net Profit | G5: Net ROI | H5: Cost / Order
A6: Organic Search | B6: =COUNTIFS(dYear,selYear,dCat,selCat,dState,selState,dVis,1,dChan,$A6) -> 1163 | C6: =SUMIFS(dSales,dYear,selYear,dCat,selCat,dState,selState,dVis,1,dChan,$A6) -> 6861148.6 | D6: =SUMIFS(dMkt,dYear,selYear,dCat,selCat,dState,selState,dVis,1,dChan,$A6) -> 510692.86 | E6: =IFERROR(C6/D6,0) -> 13.434981 | F6: =SUMIFS(dNet,dYear,selYear,dCat,selCat,dState,selState,dVis,1,dChan,$A6) -> 1558185.8 | G6: =IFERROR(F6/D6,0) -> 3.0511212 | H6: =IFERROR(D6/B6,0) -> 439.11682
A7: Google Ads | B7: =COUNTIFS(dYear,selYear,dCat,selCat,dState,selState,dVis,1,dChan,$A7) -> 989 | C7: =SUMIFS(dSales,dYear,selYear,dCat,selCat,dState,selState,dVis,1,dChan,$A7) -> 6119801.6 | D7: =SUMIFS(dMkt,dYear,selYear,dCat,selCat,dState,selState,dVis,1,dChan,$A7) -> 454573.16 | E7: =IFERROR(C7/D7,0) -> 13.462743 | F7: =SUMIFS(dNet,dYear,selYear,dCat,selCat,dState,selState,dVis,1,dChan,$A7) -> 1402118.5 | G7: =IFERROR(F7/D7,0) -> 3.0844727 | H7: =IFERROR(D7/B7,0) -> 459.62908
A8: Instagram | B8: =COUNTIFS(dYear,selYear,dCat,selCat,dState,selState,dVis,1,dChan,$A8) -> 846 | C8: =SUMIFS(dSales,dYear,selYear,dCat,selCat,dState,selState,dVis,1,dChan,$A8) -> 5533680.7 | D8: =SUMIFS(dMkt,dYear,selYear,dCat,selCat,dState,selState,dVis,1,dChan,$A8) -> 416204.9 | E8: =IFERROR(C8/D8,0) -> 13.295568 | F8: =SUMIFS(dNet,dYear,selYear,dCat,selCat,dState,selState,dVis,1,dChan,$A8) -> 1265325.8 | G8: =IFERROR(F8/D8,0) -> 3.0401511 | H8: =IFERROR(D8/B8,0) -> 491.96797
A9: Facebook Ads | B9: =COUNTIFS(dYear,selYear,dCat,selCat,dState,selState,dVis,1,dChan,$A9) -> 818 | C9: =SUMIFS(dSales,dYear,selYear,dCat,selCat,dState,selState,dVis,1,dChan,$A9) -> 4925294.3 | D9: =SUMIFS(dMkt,dYear,selYear,dCat,selCat,dState,selState,dVis,1,dChan,$A9) -> 363149.12 | E9: =IFERROR(C9/D9,0) -> 13.562732 | F9: =SUMIFS(dNet,dYear,selYear,dCat,selCat,dState,selState,dVis,1,dChan,$A9) -> 1166805.2 | G9: =IFERROR(F9/D9,0) -> 3.2130194 | H9: =IFERROR(D9/B9,0) -> 443.94758
A10: Referral | B10: =COUNTIFS(dYear,selYear,dCat,selCat,dState,selState,dVis,1,dChan,$A10) -> 628 | C10: =SUMIFS(dSales,dYear,selYear,dCat,selCat,dState,selState,dVis,1,dChan,$A10) -> 4042627 | D10: =SUMIFS(dMkt,dYear,selYear,dCat,selCat,dState,selState,dVis,1,dChan,$A10) -> 308865.29 | E10: =IFERROR(C10/D10,0) -> 13.088641 | F10: =SUMIFS(dNet,dYear,selYear,dCat,selCat,dState,selState,dVis,1,dChan,$A10) -> 908781.66 | G10: =IFERROR(F10/D10,0) -> 2.9423237 | H10: =IFERROR(D10/B10,0) -> 491.82371
A11: Email | B11: =COUNTIFS(dYear,selYear,dCat,selCat,dState,selState,dVis,1,dChan,$A11) -> 556 | C11: =SUMIFS(dSales,dYear,selYear,dCat,selCat,dState,selState,dVis,1,dChan,$A11) -> 3392112.5 | D11: =SUMIFS(dMkt,dYear,selYear,dCat,selCat,dState,selState,dVis,1,dChan,$A11) -> 253404.04 | E11: =IFERROR(C11/D11,0) -> 13.386181 | F11: =SUMIFS(dNet,dYear,selYear,dCat,selCat,dState,selState,dVis,1,dChan,$A11) -> 779608.41 | G11: =IFERROR(F11/D11,0) -> 3.0765429 | H11: =IFERROR(D11/B11,0) -> 455.76266
A38: Campaign Performance
A39: Campaign | B39: Orders | C39: Revenue | D39: Marketing Cost | E39: ROAS | F39: Net Profit | G39: Net ROI | H39: Cost / Order
A40: Regular | B40: =COUNTIFS(dYear,selYear,dCat,selCat,dState,selState,dVis,1,dCamp,$A40) -> 1407 | C40: =SUMIFS(dSales,dYear,selYear,dCat,selCat,dState,selState,dVis,1,dCamp,$A40) -> 8279732.3 | D40: =SUMIFS(dMkt,dYear,selYear,dCat,selCat,dState,selState,dVis,1,dCamp,$A40) -> 627738.97 | E40: =IFERROR(C40/D40,0) -> 13.189769 | F40: =SUMIFS(dNet,dYear,selYear,dCat,selCat,dState,selState,dVis,1,dCamp,$A40) -> 1910593.3 | G40: =IFERROR(F40/D40,0) -> 3.0436112 | H40: =IFERROR(D40/B40,0) -> 446.15421
A41: Festive Sale | B41: =COUNTIFS(dYear,selYear,dCat,selCat,dState,selState,dVis,1,dCamp,$A41) -> 897 | C41: =SUMIFS(dSales,dYear,selYear,dCat,selCat,dState,selState,dVis,1,dCamp,$A41) -> 5520691.7 | D41: =SUMIFS(dMkt,dYear,selYear,dCat,selCat,dState,selState,dVis,1,dCamp,$A41) -> 405670.6 | E41: =IFERROR(C41/D41,0) -> 13.608804 | F41: =SUMIFS(dNet,dYear,selYear,dCat,selCat,dState,selState,dVis,1,dCamp,$A41) -> 1295241.2 | G41: =IFERROR(F41/D41,0) -> 3.1928396 | H41: =IFERROR(D41/B41,0) -> 452.25262
A42: Summer Sale | B42: =COUNTIFS(dYear,selYear,dCat,selCat,dState,selState,dVis,1,dCamp,$A42) -> 728 | C42: =SUMIFS(dSales,dYear,selYear,dCat,selCat,dState,selState,dVis,1,dCamp,$A42) -> 4810752.2 | D42: =SUMIFS(dMkt,dYear,selYear,dCat,selCat,dState,selState,dVis,1,dCamp,$A42) -> 350758.94 | E42: =IFERROR(C42/D42,0) -> 13.715266 | F42: =SUMIFS(dNet,dYear,selYear,dCat,selCat,dState,selState,dVis,1,dCamp,$A42) -> 1080293.3 | G42: =IFERROR(F42/D42,0) -> 3.0798738 | H42: =IFERROR(D42/B42,0) -> 481.81173
A43: Weekend Offer | B43: =COUNTIFS(dYear,selYear,dCat,selCat,dState,selState,dVis,1,dCamp,$A43) -> 714 | C43: =SUMIFS(dSales,dYear,selYear,dCat,selCat,dState,selState,dVis,1,dCamp,$A43) -> 4311532.2 | D43: =SUMIFS(dMkt,dYear,selYear,dCat,selCat,dState,selState,dVis,1,dCamp,$A43) -> 324499.35 | E43: =IFERROR(C43/D43,0) -> 13.286721 | F43: =SUMIFS(dNet,dYear,selYear,dCat,selCat,dState,selState,dVis,1,dCamp,$A43) -> 998462.9 | G43: =IFERROR(F43/D43,0) -> 3.0769334 | H43: =IFERROR(D43/B43,0) -> 454.48088
A44: New Customer | B44: =COUNTIFS(dYear,selYear,dCat,selCat,dState,selState,dVis,1,dCamp,$A44) -> 672 | C44: =SUMIFS(dSales,dYear,selYear,dCat,selCat,dState,selState,dVis,1,dCamp,$A44) -> 4211752.3 | D44: =SUMIFS(dMkt,dYear,selYear,dCat,selCat,dState,selState,dVis,1,dCamp,$A44) -> 310303.13 | E44: =IFERROR(C44/D44,0) -> 13.573026 | F44: =SUMIFS(dNet,dYear,selYear,dCat,selCat,dState,selState,dVis,1,dCamp,$A44) -> 946089.17 | G44: =IFERROR(F44/D44,0) -> 3.0489192 | H44: =IFERROR(D44/B44,0) -> 461.76061
A45: Diwali Deals | B45: =COUNTIFS(dYear,selYear,dCat,selCat,dState,selState,dVis,1,dCamp,$A45) -> 582 | C45: =SUMIFS(dSales,dYear,selYear,dCat,selCat,dState,selState,dVis,1,dCamp,$A45) -> 3740203.9 | D45: =SUMIFS(dMkt,dYear,selYear,dCat,selCat,dState,selState,dVis,1,dCamp,$A45) -> 287918.38 | E45: =IFERROR(C45/D45,0) -> 12.990501 | F45: =SUMIFS(dNet,dYear,selYear,dCat,selCat,dState,selState,dVis,1,dCamp,$A45) -> 850145.52 | G45: =IFERROR(F45/D45,0) -> 2.952731 | H45: =IFERROR(D45/B45,0) -> 494.70512

Sheet Profitability
A1: Profitability Analytics
A2: Filtered by Dashboard selections (Year / Category / State)
A3: Gross Profit = Sales - Cost. Net Profit = Gross Profit - Shipping - Marketing cost (all orders).
A4: Monthly Profit
A5: Month | B5: Revenue | C5: Gross Profit | D5: Net Profit | E5: Gross Margin | F5: Net Margin
A6: 2025-01 | B6: =SUMIFS(dSales,dYear,selYear,dCat,selCat,dState,selState,dVis,1,dMon,$A6) -> 1470563.4 | C6: =SUMIFS(dProfit,dYear,selYear,dCat,selCat,dState,selState,dVis,1,dMon,$A6) -> 439953.35 | D6: =SUMIFS(dNet,dYear,selYear,dCat,selCat,dState,selState,dVis,1,dMon,$A6) -> 316747.36 | E6: =IFERROR(C6/B6,0) -> 0.29917334 | F6: =IFERROR(D6/B6,0) -> 0.21539185
A7: 2025-02 | B7: =SUMIFS(dSales,dYear,selYear,dCat,selCat,dState,selState,dVis,1,dMon,$A7) -> 1212539.9 | C7: =SUMIFS(dProfit,dYear,selYear,dCat,selCat,dState,selState,dVis,1,dMon,$A7) -> 388969.85 | D7: =SUMIFS(dNet,dYear,selYear,dCat,selCat,dState,selState,dVis,1,dMon,$A7) -> 277205.8 | E7: =IFERROR(C7/B7,0) -> 0.32078933 | F7: =IFERROR(D7/B7,0) -> 0.22861583
A8: 2025-03 | B8: =SUMIFS(dSales,dYear,selYear,dCat,selCat,dState,selState,dVis,1,dMon,$A8) -> 1706082.2 | C8: =SUMIFS(dProfit,dYear,selYear,dCat,selCat,dState,selState,dVis,1,dMon,$A8) -> 541152.2 | D8: =SUMIFS(dNet,dYear,selYear,dCat,selCat,dState,selState,dVis,1,dMon,$A8) -> 387621.3 | E8: =IFERROR(C8/B8,0) -> 0.31718999 | F8: =IFERROR(D8/B8,0) -> 0.22719966
A9: 2025-04 | B9: =SUMIFS(dSales,dYear,selYear,dCat,selCat,dState,selState,dVis,1,dMon,$A9) -> 1389047 | C9: =SUMIFS(dProfit,dYear,selYear,dCat,selCat,dState,selState,dVis,1,dMon,$A9) -> 431917 | D9: =SUMIFS(dNet,dYear,selYear,dCat,selCat,dState,selState,dVis,1,dMon,$A9) -> 310736.3 | E9: =IFERROR(C9/B9,0) -> 0.31094484 | F9: =IFERROR(D9/B9,0) -> 0.22370467
A10: 2025-05 | B10: =SUMIFS(dSales,dYear,selYear,dCat,selCat,dState,selState,dVis,1,dMon,$A10) -> 1694242.9 | C10: =SUMIFS(dProfit,dYear,selYear,dCat,selCat,dState,selState,dVis,1,dMon,$A10) -> 508072.85 | D10: =SUMIFS(dNet,dYear,selYear,dCat,selCat,dState,selState,dVis,1,dMon,$A10) -> 372865.31 | E10: =IFERROR(C10/B10,0) -> 0.29988195 | F10: =IFERROR(D10/B10,0) -> 0.22007784
A11: 2025-06 | B11: =SUMIFS(dSales,dYear,selYear,dCat,selCat,dState,selState,dVis,1,dMon,$A11) -> 1448851 | C11: =SUMIFS(dProfit,dYear,selYear,dCat,selCat,dState,selState,dVis,1,dMon,$A11) -> 468571 | D11: =SUMIFS(dNet,dYear,selYear,dCat,selCat,dState,selState,dVis,1,dMon,$A11) -> 336582.12 | E11: =IFERROR(C11/B11,0) -> 0.32340869 | F11: =IFERROR(D11/B11,0) -> 0.23230969
A12: 2025-07 | B12: =SUMIFS(dSales,dYear,selYear,dCat,selCat,dState,selState,dVis,1,dMon,$A12) -> 1639832.2 | C12: =SUMIFS(dProfit,dYear,selYear,dCat,selCat,dState,selState,dVis,1,dMon,$A12) -> 499652.15 | D12: =SUMIFS(dNet,dYear,selYear,dCat,selCat,dState,selState,dVis,1,dMon,$A12) -> 356173.47 | E12: =IFERROR(C12/B12,0) -> 0.30469713 | F12: =IFERROR(D12/B12,0) -> 0.21720118
A13: 2025-08 | B13: =SUMIFS(dSales,dYear,selYear,dCat,selCat,dState,selState,dVis,1,dMon,$A13) -> 1440786.9 | C13: =SUMIFS(dProfit,dYear,selYear,dCat,selCat,dState,selState,dVis,1,dMon,$A13) -> 462346.9 | D13: =SUMIFS(dNet,dYear,selYear,dCat,selCat,dState,selState,dVis,1,dMon,$A13) -> 336659.18 | E13: =IFERROR(C13/B13,0) -> 0.32089888 | F13: =IFERROR(D13/B13,0) -> 0.23366341
A14: 2025-09 | B14: =SUMIFS(dSales,dYear,selYear,dCat,selCat,dState,selState,dVis,1,dMon,$A14) -> 1530080.5 | C14: =SUMIFS(dProfit,dYear,selYear,dCat,selCat,dState,selState,dVis,1,dMon,$A14) -> 470510.5 | D14: =SUMIFS(dNet,dYear,selYear,dCat,selCat,dState,selState,dVis,1,dMon,$A14) -> 342729.83 | E14: =IFERROR(C14/B14,0) -> 0.30750702 | F14: =IFERROR(D14/B14,0) -> 0.22399464
A15: 2025-10 | B15: =SUMIFS(dSales,dYear,selYear,dCat,selCat,dState,selState,dVis,1,dMon,$A15) -> 1550397.8 | C15: =SUMIFS(dProfit,dYear,selYear,dCat,selCat,dState,selState,dVis,1,dMon,$A15) -> 458177.8 | D15: =SUMIFS(dNet,dYear,selYear,dCat,selCat,dState,selState,dVis,1,dMon,$A15) -> 335193.02 | E15: =IFERROR(C15/B15,0) -> 0.29552274 | F15: =IFERROR(D15/B15,0) -> 0.21619808
A16: 2025-11 | B16: =SUMIFS(dSales,dYear,selYear,dCat,selCat,dState,selState,dVis,1,dMon,$A16) -> 1500454.8 | C16: =SUMIFS(dProfit,dYear,selYear,dCat,selCat,dState,selState,dVis,1,dMon,$A16) -> 466844.75 | D16: =SUMIFS(dNet,dYear,selYear,dCat,selCat,dState,selState,dVis,1,dMon,$A16) -> 345881.74 | E16: =IFERROR(C16/B16,0) -> 0.31113551 | F16: =IFERROR(D16/B16,0) -> 0.23051794
A17: 2025-12 | B17: =SUMIFS(dSales,dYear,selYear,dCat,selCat,dState,selState,dVis,1,dMon,$A17) -> 1350451.9 | C17: =SUMIFS(dProfit,dYear,selYear,dCat,selCat,dState,selState,dVis,1,dMon,$A17) -> 421251.95 | D17: =SUMIFS(dNet,dYear,selYear,dCat,selCat,dState,selState,dVis,1,dMon,$A17) -> 305972.05 | E17: =IFERROR(C17/B17,0) -> 0.31193405 | F17: =IFERROR(D17/B17,0) -> 0.22657011
... A26: 2026-09 | B26: =SUMIFS(dSales,dYear,selYear,dCat,selCat,dState,selState,dVis,1,dMon,$A26) -> 1371573 | C26: =SUMIFS(dProfit,dYear,selYear,dCat,selCat,dState,selState,dVis,1,dMon,$A26) -> 452702.95 | D26: =SUMIFS(dNet,dYear,selYear,dCat,selCat,dState,selState,dVis,1,dMon,$A26) -> 342112.96 | E26: =IFERROR(C26/B26,0) -> 0.33006115 | F26: =IFERROR(D26/B26,0) -> 0.24943111
A33: Category P&L
A34: Category | B34: Revenue | C34: Cost | D34: Gross Profit | E34: Shipping | F34: Marketing | G34: Net Profit | H34: Net Margin
A35: Electronics | B35: =SUMIFS(dSales,dYear,selYear,dCat,selCat,dState,selState,dVis,1,dCat,$A35) -> 15609511 | C35: =SUMIFS(dCost,dYear,selYear,dCat,selCat,dState,selState,dVis,1,dCat,$A35) -> 11800850 | D35: =SUMIFS(dProfit,dYear,selYear,dCat,selCat,dState,selState,dVis,1,dCat,$A35) -> 3808661.3 | E35: =SUMIFS(dShip,dYear,selYear,dCat,selCat,dState,selState,dVis,1,dCat,$A35) -> 78970 | F35: =SUMIFS(dMkt,dYear,selYear,dCat,selCat,dState,selState,dVis,1,dCat,$A35) -> 1160677.9 | G35: =D35-E35-F35 -> 2569013.4 | H35: =IFERROR(G35/B35,0) -> 0.16458
A36: Home & Kitchen | B36: =SUMIFS(dSales,dYear,selYear,dCat,selCat,dState,selState,dVis,1,dCat,$A36) -> 7516883.5 | C36: =SUMIFS(dCost,dYear,selYear,dCat,selCat,dState,selState,dVis,1,dCat,$A36) -> 4887550 | D36: =SUMIFS(dProfit,dYear,selYear,dCat,selCat,dState,selState,dVis,1,dCat,$A36) -> 2629333.6 | E36: =SUMIFS(dShip,dYear,selYear,dCat,selCat,dState,selState,dVis,1,dCat,$A36) -> 85090 | F36: =SUMIFS(dMkt,dYear,selYear,dCat,selCat,dState,selState,dVis,1,dCat,$A36) -> 574040.54 | G36: =D36-E36-F36 -> 1970203 | H36: =IFERROR(G36/B36,0) -> 0.2621037
A37: Fashion | B37: =SUMIFS(dSales,dYear,selYear,dCat,selCat,dState,selState,dVis,1,dCat,$A37) -> 2995938.5 | C37: =SUMIFS(dCost,dYear,selYear,dCat,selCat,dState,selState,dVis,1,dCat,$A37) -> 1739080 | D37: =SUMIFS(dProfit,dYear,selYear,dCat,selCat,dState,selState,dVis,1,dCat,$A37) -> 1256858.5 | E37: =SUMIFS(dShip,dYear,selYear,dCat,selCat,dState,selState,dVis,1,dCat,$A37) -> 65570 | F37: =SUMIFS(dMkt,dYear,selYear,dCat,selCat,dState,selState,dVis,1,dCat,$A37) -> 221311.03 | G37: =D37-E37-F37 -> 969977.47 | H37: =IFERROR(G37/B37,0) -> 0.32376415
A38: Beauty | B38: =SUMIFS(dSales,dYear,selYear,dCat,selCat,dState,selState,dVis,1,dCat,$A38) -> 1904279.3 | C38: =SUMIFS(dCost,dYear,selYear,dCat,selCat,dState,selState,dVis,1,dCat,$A38) -> 1068000 | D38: =SUMIFS(dProfit,dYear,selYear,dCat,selCat,dState,selState,dVis,1,dCat,$A38) -> 836279.3 | E38: =SUMIFS(dShip,dYear,selYear,dCat,selCat,dState,selState,dVis,1,dCat,$A38) -> 32920 | F38: =SUMIFS(dMkt,dYear,selYear,dCat,selCat,dState,selState,dVis,1,dCat,$A38) -> 140652.4 | G38: =D38-E38-F38 -> 662706.9 | H38: =IFERROR(G38/B38,0) -> 0.3480093
A39: Sports | B39: =SUMIFS(dSales,dYear,selYear,dCat,selCat,dState,selState,dVis,1,dCat,$A39) -> 1600075 | C39: =SUMIFS(dCost,dYear,selYear,dCat,selCat,dState,selState,dVis,1,dCat,$A39) -> 939120 | D39: =SUMIFS(dProfit,dYear,selYear,dCat,selCat,dState,selState,dVis,1,dCat,$A39) -> 660954.95 | E39: =SUMIFS(dShip,dYear,selYear,dCat,selCat,dState,selState,dVis,1,dCat,$A39) -> 32910 | F39: =SUMIFS(dMkt,dYear,selYear,dCat,selCat,dState,selState,dVis,1,dCat,$A39) -> 116759.56 | G39: =D39-E39-F39 -> 511285.39 | H39: =IFERROR(G39/B39,0) -> 0.3195384
A40: Accessories | B40: =SUMIFS(dSales,dYear,selYear,dCat,selCat,dState,selState,dVis,1,dCat,$A40) -> 1247977.1 | C40: =SUMIFS(dCost,dYear,selYear,dCat,selCat,dState,selState,dVis,1,dCat,$A40) -> 722600 | D40: =SUMIFS(dProfit,dYear,selYear,dCat,selCat,dState,selState,dVis,1,dCat,$A40) -> 525377.05 | E40: =SUMIFS(dShip,dYear,selYear,dCat,selCat,dState,selState,dVis,1,dCat,$A40) -> 34290 | F40: =SUMIFS(dMkt,dYear,selYear,dCat,selCat,dState,selState,dVis,1,dCat,$A40) -> 93447.89 | G40: =D40-E40-F40 -> 397639.16 | H40: =IFERROR(G40/B40,0) -> 0.31862698
A51: Margin by Discount Level
A52: Discount | B52: Revenue | C52: Gross Profit | D52: Margin
A53: 0 | B53: =SUMIFS(dSales,dYear,selYear,dCat,selCat,dState,selState,dVis,1,dDisc,$A53) -> 6706361 | C53: =SUMIFS(dProfit,dYear,selYear,dCat,selCat,dState,selState,dVis,1,dDisc,$A53) -> 2526131 | D53: =IFERROR(C53/B53,0) -> 0.37667686
A54: 0.05 | B54: =SUMIFS(dSales,dYear,selYear,dCat,selCat,dState,selState,dVis,1,dDisc,$A54) -> 8086063.7 | C54: =SUMIFS(dProfit,dYear,selYear,dCat,selCat,dState,selState,dVis,1,dDisc,$A54) -> 2812713.7 | D54: =IFERROR(C54/B54,0) -> 0.34784709
A55: 0.1 | B55: =SUMIFS(dSales,dYear,selYear,dCat,selCat,dState,selState,dVis,1,dDisc,$A55) -> 7158181.5 | C55: =SUMIFS(dProfit,dYear,selYear,dCat,selCat,dState,selState,dVis,1,dDisc,$A55) -> 2219441.5 | D55: =IFERROR(C55/B55,0) -> 0.31005661
A56: 0.15 | B56: =SUMIFS(dSales,dYear,selYear,dCat,selCat,dState,selState,dVis,1,dDisc,$A56) -> 5470980.8 | C56: =SUMIFS(dProfit,dYear,selYear,dCat,selCat,dState,selState,dVis,1,dDisc,$A56) -> 1472860.8 | D56: =IFERROR(C56/B56,0) -> 0.2692133
A57: 0.2 | B57: =SUMIFS(dSales,dYear,selYear,dCat,selCat,dState,selState,dVis,1,dDisc,$A57) -> 2263591.2 | C57: =SUMIFS(dProfit,dYear,selYear,dCat,selCat,dState,selState,dVis,1,dDisc,$A57) -> 499351.2 | D57: =IFERROR(C57/B57,0) -> 0.22060132
A58: 0.25 | B58: =SUMIFS(dSales,dYear,selYear,dCat,selCat,dState,selState,dVis,1,dDisc,$A58) -> 1189486.5 | C58: =SUMIFS(dProfit,dYear,selYear,dCat,selCat,dState,selState,dVis,1,dDisc,$A58) -> 186966.5 | D58: =IFERROR(C58/B58,0) -> 0.15718253

Sheet Customer_List
A1: Customer_ID | B1: Customer_Name | C1: Orders | D1: Revenue | E1: Rank_Key | G1: All-time customer totals (not filtered by dashboard selections)
A2: C0149 | B2: Customer 149 | C2: =COUNTIF(dCust,A2) -> 10 | D2: =SUMIFS(dSales,dCust,A2) -> 151311.2 | E2: =D2+ROW()/1000000 -> 151311.2
A3: C0161 | B3: Customer 161 | C3: =COUNTIF(dCust,A3) -> 7 | D3: =SUMIFS(dSales,dCust,A3) -> 149180.35 | E3: =D3+ROW()/1000000 -> 149180.35
A4: C0960 | B4: Customer 960 | C4: =COUNTIF(dCust,A4) -> 7 | D4: =SUMIFS(dSales,dCust,A4) -> 118298.4 | E4: =D4+ROW()/1000000 -> 118298.4
A5: C0986 | B5: Customer 986 | C5: =COUNTIF(dCust,A5) -> 5 | D5: =SUMIFS(dSales,dCust,A5) -> 116497.4 | E5: =D5+ROW()/1000000 -> 116497.4
A6: C0097 | B6: Customer 97 | C6: =COUNTIF(dCust,A6) -> 6 | D6: =SUMIFS(dSales,dCust,A6) -> 112896.7 | E6: =D6+ROW()/1000000 -> 112896.7
A7: C0484 | B7: Customer 484 | C7: =COUNTIF(dCust,A7) -> 10 | D7: =SUMIFS(dSales,dCust,A7) -> 110155.25 | E7: =D7+ROW()/1000000 -> 110155.25
A8: C0944 | B8: Customer 944 | C8: =COUNTIF(dCust,A8) -> 7 | D8: =SUMIFS(dSales,dCust,A8) -> 103899.3 | E8: =D8+ROW()/1000000 -> 103899.3
A9: C0011 | B9: Customer 11 | C9: =COUNTIF(dCust,A9) -> 4 | D9: =SUMIFS(dSales,dCust,A9) -> 102681.45 | E9: =D9+ROW()/1000000 -> 102681.45
A10: C0623 | B10: Customer 623 | C10: =COUNTIF(dCust,A10) -> 7 | D10: =SUMIFS(dSales,dCust,A10) -> 97972.25 | E10: =D10+ROW()/1000000 -> 97972.25
A11: C0810 | B11: Customer 810 | C11: =COUNTIF(dCust,A11) -> 5 | D11: =SUMIFS(dSales,dCust,A11) -> 97531.35 | E11: =D11+ROW()/1000000 -> 97531.35
A12: C0132 | B12: Customer 132 | C12: =COUNTIF(dCust,A12) -> 7 | D12: =SUMIFS(dSales,dCust,A12) -> 97303.9 | E12: =D12+ROW()/1000000 -> 97303.9
A13: C0224 | B13: Customer 224 | C13: =COUNTIF(dCust,A13) -> 3 | D13: =SUMIFS(dSales,dCust,A13) -> 94902.9 | E13: =D13+ROW()/1000000 -> 94902.9
... A1183: C0033 | B1183: Customer 33 | C1183: =COUNTIF(dCust,A1183) -> 1 | D1183: =SUMIFS(dSales,dCust,A1183) -> 0 | E1183: =D1183+ROW()/1000000 -> 0.001183

Sheet Data
A1: Order_ID | B1: Order_Date | C1: Year | D1: Month | E1: Month_Name | F1: Quarter | G1: Customer_ID | H1: Customer_Name | I1: Gender | J1: Age | K1: Age_Group | L1: City | M1: State | N1: Product_ID | O1: Product_Name | P1: Category | Q1: Sub_Category | R1: Quantity | S1: Unit_Price | T1: Discount | U1: Sales | V1: Cost | W1: Profit | X1: Payment_Mode | Y1: Order_Status | Z1: Marketing_Channel | AA1: Campaign | AB1: Rating | AC1: Shipping_Cost | AD1: Marketing_Cost | AE1: Net_Profit | AF1: Year_Month | AG1: Visible
A2: ORD004686 | B2: 45658 | C2: 2025 | D2: 1 | E2: Jan | F2: Q1 | G2: C0615 | H2: Customer 615 | I2: Female | J2: 19 | K2: 18-25 | L2: Siliguri | M2: West Bengal | N2: P016 | O2: Sunglasses | P2: Fashion | Q2: Accessories | R2: 5 | S2: 1199 | T2: 0 | U2: 0 | V2: 0 | W2: 0 | X2: UPI | Y2: Cancelled | Z2: Organic Search | AA2: Festive Sale | AB2: 4.3 | AC2: 60 | AD2: 171.44 | AE2: =W2-AC2-AD2 -> -231.44 | AF2: =C2&"-"&TEXT(D2,"00") -> 2025-01 | AG2: =SUBTOTAL(103,A2) -> 1
A3: ORD000757 | B3: 45658 | C3: 2025 | D3: 1 | E3: Jan | F3: Q1 | G3: C0200 | H3: Customer 200 | I3: Female | J3: 26 | K3: 26-35 | L3: Udaipur | M3: Rajasthan | N3: P014 | O3: LED Study Lamp | P3: Home & Kitchen | Q3: Lighting | R3: 2 | S3: 1299 | T3: 0.05 | U3: 2468.1 | V3: 1300 | W3: 1168.1 | X3: Net Banking | Y3: Delivered | Z3: Facebook Ads | AA3: Festive Sale | AB3: 4 | AC3: 60 | AD3: 152.95 | AE3: =W3-AC3-AD3 -> 955.15 | AF3: =C3&"-"&TEXT(D3,"00") -> 2025-01 | AG3: =SUBTOTAL(103,A3) -> 1
A4: ORD000708 | B4: 45658 | C4: 2025 | D4: 1 | E4: Jan | F4: Q1 | G4: C0908 | H4: Customer 908 | I4: Male | J4: 20 | K4: 18-25 | L4: Nashik | M4: Maharashtra | N4: P002 | O4: Smart Watch | P4: Electronics | Q4: Wearables | R4: 1 | S4: 3999 | T4: 0.2 | U4: 3199.2 | V4: 2400 | W4: 799.2 | X4: Credit Card | Y4: Delivered | Z4: Google Ads | AA4: Festive Sale | AB4: 4 | AC4: 50 | AD4: 120.39 | AE4: =W4-AC4-AD4 -> 628.81 | AF4: =C4&"-"&TEXT(D4,"00") -> 2025-01 | AG4: =SUBTOTAL(103,A4) -> 1
A5: ORD002080 | B5: 45658 | C5: 2025 | D5: 1 | E5: Jan | F5: Q1 | G5: C0530 | H5: Customer 530 | I5: Female | J5: 33 | K5: 26-35 | L5: Siliguri | M5: West Bengal | N5: P008 | O5: Coffee Maker | P5: Home & Kitchen | Q5: Kitchen | R5: 1 | S5: 3499 | T5: 0.15 | U5: 2974.15 | V5: 2100 | W5: 874.15 | X5: UPI | Y5: Delivered | Z5: Instagram | AA5: Festive Sale | AB5: 3.9 | AC5: 80 | AD5: 282.07 | AE5: =W5-AC5-AD5 -> 512.08 | AF5: =C5&"-"&TEXT(D5,"00") -> 2025-01 | AG5: =SUBTOTAL(103,A5) -> 1
A6: ORD004948 | B6: 45658 | C6: 2025 | D6: 1 | E6: Jan | F6: Q1 | G6: C0404 | H6: Customer 404 | I6: Female | J6: 55 | K6: 46-60 | L6: Siliguri | M6: West Bengal | N6: P005 | O6: Running Shoes | P6: Fashion | Q6: Footwear | R6: 1 | S6: 2999 | T6: 0.2 | U6: 2399.2 | V6: 1700 | W6: 699.2 | X6: Cash on Delivery | Y6: Delivered | Z6: Organic Search | AA6: Diwali Deals | AB6: 3.3 | AC6: 80 | AD6: 246.37 | AE6: =W6-AC6-AD6 -> 372.83 | AF6: =C6&"-"&TEXT(D6,"00") -> 2025-01 | AG6: =SUBTOTAL(103,A6) -> 1
A7: ORD000988 | B7: 45658 | C7: 2025 | D7: 1 | E7: Jan | F7: Q1 | G7: C0985 | H7: Customer 985 | I7: Female | J7: 36 | K7: 36-45 | L7: Ahmedabad | M7: Gujarat | N7: P011 | O7: Mobile Phone | P7: Electronics | Q7: Mobiles | R7: 2 | S7: 14999 | T7: 0.15 | U7: 25498.3 | V7: 22400 | W7: 3098.3 | X7: Debit Card | Y7: Delivered | Z7: Instagram | AA7: New Customer | AB7: 4 | AC7: 80 | AD7: 690.19 | AE7: =W7-AC7-AD7 -> 2328.11 | AF7: =C7&"-"&TEXT(D7,"00") -> 2025-01 | AG7: =SUBTOTAL(103,A7) -> 1
A8: ORD000531 | B8: 45658 | C8: 2025 | D8: 1 | E8: Jan | F8: Q1 | G8: C0486 | H8: Customer 486 | I8: Female | J8: 39 | K8: 36-45 | L8: Warangal | M8: Telangana | N8: P017 | O8: Skincare Kit | P8: Beauty | Q8: Skincare | R8: 4 | S8: 1599 | T8: 0.05 | U8: 6076.2 | V8: 3200 | W8: 2876.2 | X8: Credit Card | Y8: Delivered | Z8: Instagram | AA8: Festive Sale | AB8: 3.9 | AC8: 100 | AD8: 336.95 | AE8: =W8-AC8-AD8 -> 2439.25 | AF8: =C8&"-"&TEXT(D8,"00") -> 2025-01 | AG8: =SUBTOTAL(103,A8) -> 1
A9: ORD004781 | B9: 45658 | C9: 2025 | D9: 1 | E9: Jan | F9: Q1 | G9: C0543 | H9: Customer 543 | I9: Male | J9: 57 | K9: 46-60 | L9: Delhi | M9: Delhi | N9: P012 | O9: Tablet | P9: Electronics | Q9: Tablets | R9: 3 | S9: 12999 | T9: 0.1 | U9: 35097.3 | V9: 27000 | W9: 8097.3 | X9: UPI | Y9: Delivered | Z9: Instagram | AA9: Weekend Offer | AB9: 3.5 | AC9: 50 | AD9: 2195.18 | AE9: =W9-AC9-AD9 -> 5852.12 | AF9: =C9&"-"&TEXT(D9,"00") -> 2025-01 | AG9: =SUBTOTAL(103,A9) -> 1
A10: ORD000379 | B10: 45658 | C10: 2025 | D10: 1 | E10: Jan | F10: Q1 | G10: C0875 | H10: Customer 875 | I10: Other | J10: 52 | K10: 46-60 | L10: Lucknow | M10: Uttar Pradesh | N10: P015 | O10: Backpack | P10: Accessories | Q10: Bags | R10: 1 | S10: 999 | T10: 0.15 | U10: 849.15 | V10: 520 | W10: 329.15 | X10: Debit Card | Y10: Delivered | Z10: Organic Search | AA10: Festive Sale | AB10: 4.3 | AC10: 50 | AD10: 20 | AE10: =W10-AC10-AD10 -> 259.15 | AF10: =C10&"-"&TEXT(D10,"00") -> 2025-01 | AG10: =SUBTOTAL(103,A10) -> 1
A11: ORD001696 | B11: 45658 | C11: 2025 | D11: 1 | E11: Jan | F11: Q1 | G11: C0493 | H11: Customer 493 | I11: Male | J11: 55 | K11: 46-60 | L11: Delhi | M11: Delhi | N11: P018 | O11: Perfume | P11: Beauty | Q11: Fragrance | R11: 1 | S11: 2299 | T11: 0.05 | U11: 2184.05 | V11: 1200 | W11: 984.05 | X11: Cash on Delivery | Y11: Delivered | Z11: Organic Search | AA11: Regular | AB11: 2.9 | AC11: 80 | AD11: 246.22 | AE11: =W11-AC11-AD11 -> 657.83 | AF11: =C11&"-"&TEXT(D11,"00") -> 2025-01 | AG11: =SUBTOTAL(103,A11) -> 1
A12: ORD003432 | B12: 45658 | C12: 2025 | D12: 1 | E12: Jan | F12: Q1 | G12: C0498 | H12: Customer 498 | I12: Female | J12: 40 | K12: 36-45 | L12: Varanasi | M12: Uttar Pradesh | N12: P005 | O12: Running Shoes | P12: Fashion | Q12: Footwear | R12: 2 | S12: 2999 | T12: 0.05 | U12: 5698.1 | V12: 3400 | W12: 2298.1 | X12: Credit Card | Y12: Delivered | Z12: Instagram | AA12: Festive Sale | AB12: 4.7 | AC12: 40 | AD12: 539.58 | AE12: =W12-AC12-AD12 -> 1718.52 | AF12: =C12&"-"&TEXT(D12,"00") -> 2025-01 | AG12: =SUBTOTAL(103,A12) -> 1
A13: ORD000936 | B13: 45659 | C13: 2025 | D13: 1 | E13: Jan | F13: Q1 | G13: C0801 | H13: Customer 801 | I13: Female | J13: 57 | K13: 46-60 | L13: Vadodara | M13: Gujarat | N13: P002 | O13: Smart Watch | P13: Electronics | Q13: Wearables | R13: 2 | S13: 3999 | T13: 0.2 | U13: 6398.4 | V13: 4800 | W13: 1598.4 | X13: Credit Card | Y13: Delivered | Z13: Email | AA13: Festive Sale | AB13: 4.5 | AC13: 100 | AD13: 589.02 | AE13: =W13-AC13-AD13 -> 909.38 | AF13: =C13&"-"&TEXT(D13,"00") -> 2025-01 | AG13: =SUBTOTAL(103,A13) -> 1
